Workbook

Sheet For Hire 2008-09
A1: Rank | B1: Rank | C1: Company | D1: Revenue | E1: Net income | F1: Employee | G1: Tractors | H1: Truck &Van | I1: Trailers | J1: aircraft | K1: container | L1: chassis | N1: SCAC_Self
A2: 2009 | B2: 2008 | D2: thousand
A3: Rank | C3: Company | D3: Revenue | E3: NetIncome | F3: NumberEmployees | G3: NumberTractors | H3: NumberTruckVans | I3: NumberTrailers | J3: Aircraft | K3: Container | L3: Chassis | M3: AssetYear | N3: SCAC_Self
A4: 1 | B4: 1 | C4: UPS Inc | D4: 45297000 | E4: 2152000 | F4: 408000 | G4: 12268 | H4: 66425 | I4: 22015 | J4: 253 | M4: 2010 | N4: UPSF
A5: 2 | B5: 2 | C5: FedEx Corp | D5: 34734000 | E5: 1184000 | F5: 280000 | G5: 22800 | H5: 60900 | I5: 0 | J5: 664 | M5: 2010 | N5: FDTB
A6: 3 | B6: 3 | C6: DHL USA | D6: 6586872 | G6: 46 | H6: 2683 | I6: 28 | M6: 2010 | N6: DMAL
A7: 4 | B7: 4 | C7: YRC Worldwide Inc. | D7: 5282778 | E7: -622019 | F7: 36000 | G7: 18600 | H7: 400 | I7: 65600 | M7: 2010 | N7: RDWY
A8: 5 | B8: 5 | C8: Ryder System | D8: 4887254 | E8: 61945 | F8: 22900 | G8: 49328 | H8: 72527 | I8: 49660 | M8: 2010 | N8: Ryder
A9: 6 | B9: 6 | C9: Con-way Inc. | D9: 4269239 | E9: -110936 | F9: 27400 | G9: 49328 | H9: 72527 | I9: 49660 | M9: 2010 | N9: CNWY
A10: 7 | B10: 7 | C10: Penske Truck Leasing Co | D10: 4000000 | F10: 18000 | G10: 12060 | H10: 105 | I10: 33028 | M10: 2010 | N10: PSKL
A11: 8 | B11: 8 | C11: J.B. Hunt Transport Services | D11: 3203321 | E11: 136435 | F11: 14171 | G11: 0 | H11: 151350 | I11: 53200 | M11: 2010 | N11: QPMT
A12: 9 | B12: 9 | C12: Schneider National Inc | D12: 2900000 | F12: 18468 | G12: 9169 | H12: 0 | I12: 21951 | K12: 40236 | M12: 2010 | N12: SCNN
A13: 10 | B13: 10 | C13: Swift Transportation | D13: 2571000 | F13: 15500 | G13: 16025 | H13: 0 | I13: 49200 | K13: 4300 | M13: 2010 | N13: SWFT
A14: 11 | B14: 13 | C14: Landstar System | D14: 2008796 | E14: 69950 | F14: 1374 | G14: 8519 | H14: 0 | I14: 13302 | M14: 2010 | N14: LRGR
A15: 12 | B15: 12 | C15: Sirva Inc. | D15: 1698900 | F15: 2600 | G15: 2627 | H15: 1477 | I15: 4362 | M15: 2010 | N15: Sirva | O15: not found
A16: 13 | B16: 14 | C16: Werner Enterprises | D16: 1666470 | E16: 56584 | F16: 11352 | G16: 7250 | H16: 0 | I16: 23880 | M16: 2010 | N16: WENP
A17: 14 | B17: 15 | C17: TransForce Inc. | D17: 1618111 | E17: 9577 | F17: 13900 | G17: 6700 | H17: 0 | I17: 12000 | M17: 2010 | N17: TransForce | O17: not found
A18: 15 | B18: 17 | C18: UniGroup Inc. | D18: 1600000 | F18: 1050 | G18: 6401 | H18: 4343 | I18: 10615 | K18: 735 | M18: 2010 | N18: AERM
A19: 16 | B19: 18 | C19: Arkansas Best Corp. | D19: 1472901 | E19: -127889 | F19: 10347 | G19: 3962 | H19: 73 | I19: 19764 | M19: 2010 | N19: Arkansas | O19: not found
A20: 17 | B20: 19 | C20: U.S. Xpress Enterprises | D20: 1394537 | F20: 10566 | G20: 8536 | H20: 0 | I20: 21458 | M20: 2010 | N20: USXI
A21: 18 | B21: 21 | C21: Estes Express Lines | D21: 1304000 | F21: 12469 | G21: 5547 | H21: 315 | I21: 21994 | M21: 2010 | N21: EXLA
A22: 19 | B22: 22 | C22: Purolator Courier Ltd. | D22: 1256245 | F22: 11300 | G22: 493 | H22: 3833 | I22: 1113 | J22: 18 | M22: 2010 | N22: Purolator | O22: not found
A23: 20 | B23: 20 | C23: Old Dominion Freight Line | D23: 1245005 | E23: 34871 | F23: 9608 | G23: 5390 | H23: 114 | I23: 21185 | M23: 2010 | N23: ODFL
A24: 21 | B24: 23 | C24: Greatwide Logistics Services | D24: 1000000 | F24: 3200 | G24: 4967 | H24: 0 | I24: 5628 | M24: 2010 | N24: ATGL
A25: 22 | B25: 30 | C25: C.R. England Inc. | D25: 919092 | E25: 48521 | F25: 5531 | G25: 3552 | H25: 0 | I25: 5425 | K25: 320 | M25: 2010 | N25: ENGI
A26: 23 | B26: 24 | C26: Crete Carrier Corp. | D26: 850000 | F26: 5750 | G26: 5100 | H26: 0 | I26: 13500 | M26: 2010 | N26: CRCR
A27: 24 | B27: 25 | C27: Saia Inc. | D27: 849141 | E27: -7875 | F27: 7200 | G27: 3390 | H27: 127 | I27: 11089 | M27: 2010 | N27: SAIA
A28: 25 | B28: 32 | C28: Prime Inc | D28: 837382 | E28: 92248 | F28: 3528 | G28: 4418 | H28: 0 | I28: 6149 | M28: 2010 | N28: PDSI
A29: 26 | B29: 35 | C29: NFI Industries | D29: 810000 | F29: 5500 | G29: 2233 | H29: 0 | I29: 7350 | M29: 2010 | N29: NFAQ
A30: 27 | B30: 26 | C30: Averitt Express | D30: 768348 | G30: 3668 | H30: 48 | I30: 12210 | M30: 2010 | N30: AVRT
A31: 28 | B31: 27 | C31: Atlas World Group | D31: 715000 | F31: 350 | G31: 2321 | H31: 1670 | I31: 4218 | M31: 2010 | N31: ALQK
A32: 29 | B32: 33 | C32: Southeastern Freight Lines | D32: 703354 | F32: 6883 | G32: 3136 | H32: 27 | I32: 9387 | M32: 2010 | N32: SEFL
A33: 30 | B33: 31 | C33: Ruan Transportation Management Systems | D33: 680134 | F33: 4553 | G33: 2666 | H33: 18 | I33: 4450 | M33: 2010 | N33: RLCF
A34: 31 | B34: 36 | C34: Lynden Inc. | D34: 680000 | F34: 2267 | G34: 711 | H34: 62 | I34: 2735 | K34: 5605 | M34: 2010 | N34: LTIA
A35: 32 | B35: 28 | C35: CRST International | D35: 679622 | F35: 3740 | G35: 2952 | H35: 0 | I35: 4973 | M35: 2010 | N35: CRFR
A36: 33 | B36: 42 | C36: Kenan Advantage Group | D36: 672113 | F36: 5622 | G36: 3231 | H36: 0 | I36: 3294 | M36: 2010 | N36: AVTK
A37: 34 | B37: 38 | C37: Knight Transportation | D37: 651721 | E37: 50563 | F37: 4500 | G37: 3736 | H37: 0 | I37: 8493 | M37: 2010 | N37: Knight | O37: subsidiaries found
A38: 35 | B38: 40 | C38: Vitran Corp. | D38: 629260 | E38: -3972 | F38: 4832 | G38: 2338 | H38: 0 | I38: 6967 | K38: 519 | L38: 451 | M38: 2010 | N38: VITR
A39: 36 | B39: 34 | C39: Quality Distribution Inc. | D39: 613609 | E39: -180534 | F39: 810 | G39: 2839 | H39: 0 | I39: 6410 | M39: 2010 | N39: QTKI
A40: 37 | B40: 37 | C40: Covenant Transportation Group | D40: 588687 | E40: -25030 | F40: 4819 | G40: 3206 | H40: 0 | I40: 8005 | M40: 2010 | N40: CVTH
...

Sheet For Hire 2009-10
A1: Rank | B1: Rank | C1: Company | D1: Revenue | E1: Net income | F1: Employee | G1: Tractors | H1: Truck &Van | I1: Trailers | J1: aircraft | K1: container | L1: chassis | N1: SCAC_Self
A2: 2010 | B2: 2009 | D2: thousand
A3: Rank | C3: Company | D3: Revenue | E3: NetIncome | F3: NumberEmployees | G3: NumberTractors | H3: NumberTruckVans | I3: NumberTrailers | J3: Aircraft | K3: Container | L3: Chassis | M3: AssetYear | N3: SCAC_Self
A4: 1 | B4: 1 | C4: UPS Inc | D4: 49600000 | E4: 3500000 | F4: 400600 | G4: =12268/(12268+66425)*99800 -> 15558.517 | H4: =66425/(12268+66425)*99800 -> 84241.483 | I4: 21090 | J4: 216 | M4: 2011 | N4: UPSF
A5: 2 | B5: 2 | C5: FedEx Corp | D5: 38180000 | E5: 1125000 | F5: 285000 | G5: 22803 | H5: 52353 | I5: 80281 | J5: 697 | M5: 2011 | N5: FDTB
A6: 3 | B6: 6 | C6: Con-way Inc. | D6: 4952000 | E6: 78200 | F6: 27900 | G6: 11952 | H6: 105 | I6: 34400 | M6: 2011 | N6: CNWY
A7: 4 | B7: 4 | C7: YRC Worldwide | D7: 4334640 | E7: -230600 | F7: 32000 | G7: 16152 | H7: 0 | I7: 52098 | M7: 2011 | N7: RDWY
A8: 5 | B8: 8 | C8: J.B. Hunt Transport Services | D8: 3793485 | E8: 199617 | F8: 15223 | G8: 9543 | H8: 0 | I8: 20803 | K8: 45666 | M8: 2011 | N8: QPMT
A9: 6 | B9: 9 | C9: Schneider National Inc | D9: 3100000 | F9: 18395 | G9: 11634 | H9: 0 | I9: 32608 | K9: 12600 | M9: 2011 | N9: SCNN
A10: 7 | B10: 10 | C10: Swift Transportation | D10: 2929723 | E10: -125413 | F10: 18000 | G10: 16100 | H10: 0 | I10: 48992 | K10: 4800 | M10: 2011 | N10: SWFT
A11: 8 | B11: 11 | C11: Landstar System | D11: 2400170 | E11: 87514 | F11: 1353 | G11: 8452 | H11: 0 | I11: 13084 | M11: 2011 | N11: LRGR
A12: 9 | B12: 7 | C12: Penske Logistics | D12: 2400000 | F12: 9000 | G12: 2115 | H12: 289 | I12: 2969 | M12: 2011 | N12: PSKL
A13: 10 | B13: 14 | C13: TransForce Inc | D13: 1942746 | E13: 101504 | F13: 11600 | G13: 4906 | H13: 1294 | I13: 10684 | L13: 916 | M13: 2011 | N13: TransForce | O13: not found
A14: 11 | B14: 13 | C14: Werner Enterprises | D14: 1815020 | E14: 80039 | F14: 11916 | G14: 7275 | H14: 0 | I14: 23850 | M14: 2011 | N14: WENP
A15: 12 | B15: 5 | C15: Ryder Supply Chain Solutions | D15: 1734834 | F15: 15017 | G15: 3272 | H15: 707 | I15: 5455 | M15: 2011 | N15: Ryder
A16: 13 | B16: 12 | C16: Sirva Inc. | D16: 1731900 | F16: 2300 | G16: 2510 | H16: 1388 | I16: 8002 | M16: 2011 | N16: Sirva
A17: 14 | B17: 16 | C17: Arkansas Best Corp. | D17: 1657864 | E17: -32693 | F17: 10750 | G17: 3821 | H17: 63 | I17: 19285 | M17: 2011 | N17: Arkansas | O17: not found
A18: 15 | B18: 17 | C18: U.S. Xpress Enterprises | D18: 1585283 | F18: 9250 | G18: 8517 | H18: 0 | I18: 22000 | M18: 2011 | N18: USXI
A19: 16 | B19: 15 | C19: UniGroup Inc. | D19: 1520000 | F19: 800 | G19: 6204 | H19: 4650 | I19: 10400 | K19: 6600 | M19: 2011 | N19: AERM
A20: 17 | B20: 18 | C20: Estes Express Lines | D20: 1502510 | F20: 13412 | G20: 6009 | H20: 371 | I20: 22120 | M20: 2011 | N20: EXLA
A21: 18 | B21: 20 | C21: Old Dominion Freight Line | D21: 1480998 | E21: 117 | F21: 12457 | G21: 5718 | H21: 112 | I21: 20986 | L21: 52 | M21: 2011 | N21: ODFL
A22: 19 | B22: 19 | C22: Purolator Inc. | D22: 1448777 | F22: 11300 | G22: 432 | H22: 3273 | I22: 1149 | M22: 2011 | N22: Purolator | O22: not found
A23: 20 | B23: 21 | C23: Greatwide Logistics Services | D23: 1022027 | F23: 3300 | G23: 4089 | H23: 0 | I23: 5200 | M23: 2011 | N23: ATGL
A24: 21 | B24: 22 | C24: C.R. England Inc. | D24: 934669 | E24: 47716 | F24: 6109 | G24: 3747 | H24: 0 | I24: 5444 | K24: 320 | M24: 2011 | N24: ENGI
A25: 22 | B25: 25 | C25: Prime Inc. | D25: 931787 | E25: 93818 | F25: 3565 | G25: 4392 | H25: 0 | I25: 6828 | M25: 2011 | N25: PDSI
A26: 23 | B26: 24 | C26: Saia Inc. | D26: 902660 | E26: 1957 | F26: 7500 | G26: 3525 | H26: 130 | I26: 10900 | M26: 2011 | N26: NFAQ
A27: 24 | B27: 26 | C27: NFI Industries | D27: 90000 | F27: 5600 | G27: 1907 | H27: 235 | I27: 6851 | K27: 49 | M27: 2011 | N27: SAIA
A28: 25 | B28: 23 | C28: Crete Carrier Corp. | D28: 850311 | F28: 5815 | G28: 5260 | H28: 0 | I28: 13400 | M28: 2011 | N28: CRCR
A29: 26 | B29: 32 | C29: CRST International | D29: 838193 | F29: 6490 | G29: 3427 | H29: 0 | I29: 6031 | M29: 2011 | N29: CRFR
A30: 27 | B30: 29 | C30: Southeastern Freight Lines | D30: 826755 | F30: 7360 | G30: 2778 | H30: 23 | I30: 9189 | M30: 2011 | N30: SEFL
A31: 28 | B31: 27 | C31: Averitt Express | D31: 824000 | G31: 3720 | H31: 46 | I31: 12082 | M31: 2011 | N31: AVRT
A32: 29 | B32: 33 | C32: Kenan Advantage Group | D32: 772447 | F32: 6245 | G32: 4038 | H32: 0 | I32: 5382 | M32: 2011 | N32: AVTK
A33: 30 | B33: 28 | C33: Atlas World Group | D33: 759998 | F33: 636 | G33: 2206 | H33: 1612 | I33: 4063 | K33: 5648 | M33: 2011 | N33: ALQK
A34: 31 | B34: 34 | C34: Knight Transportation | D34: 730709 | E34: 59072 | F34: 4526 | G34: 3866 | H34: 0 | I34: 8960 | L34: 48 | M34: 2011 | N34: Knight | O34: subsidiaries found
A35: 32 | B35: 31 | C35: Lynden Inc. | D35: 720000 | F35: 2198 | G35: 693 | H35: 94 | I35: 2773 | K35: 5578 | L35: 1624 | M35: 2011 | N35: LTIA
A36: 33 | B36: 36 | C36: Quality Distribution Inc. | D36: 686598 | E36: -7406 | F36: 752 | G36: 2901 | H36: 0 | I36: 5738 | M36: 2011 | N36: QTKI
A37: 34 | B37: 35 | C37: Vitran Corp. | D37: 672556 | E37: -40182 | F37: 4895 | G37: 2134 | H37: 0 | I37: 6158 | K37: 513 | L37: 451 | M37: 2011 | N37: VITR
A38: 35 | B38: 30 | C38: Ruan Transportation Management Systems | D38: 669905 | F38: 4603 | G38: 3036 | H38: 25 | I38: 7443 | M38: 2011 | N38: RLCF
A39: 36 | B39: 37 | C39: Covenant Transportation group | D39: 649749 | E39: 3289 | F39: 4740 | G39: 3059 | H39: 0 | I39: 7332 | M39: 2011 | N39: CVTH
A40: 37 | C40: Day & Ross Transportation group | D40: 643583 | F40: 4318 | G40: 2154 | H40: 170 | I40: 3858 | M40: 2011 | N40: DAYR
...

Sheet For Hire 2011-12
A1: Rank | B1: Rank | C1: Company | D1: Revenue | E1: Net income | F1: Employee | G1: Tractors | H1: Truck &Van | I1: Trailers | J1: aircraft | K1: container | L1: chassis | N1: SCAC_Self
A2: 2012 | B2: 2011 | D2: thousand
A3: Rank | C3: Company | D3: Revenue | E3: NetIncome | F3: NumberEmployees | G3: NumberTractors | H3: NumberTruckVans | I3: NumberTrailers | J3: Aircraft | K3: Container | L3: Chassis | M3: AssetYear | N3: SCAC_Self
A4: 1 | B4: 1 | C4: UPS Inc | D4: 54127000 | E4: 807000 | F4: 399000 | G4: =102851*12268/(12268+66425) -> 16034.159 | H4: =102851*66425/(12268+66425) -> 86816.841 | I4: 83730 | J4: 230 | M4: 2013 | N4: UPSF
A5: 2 | B5: 2 | C5: FedEx Corp | D5: 43898000 | E5: 1808000 | F5: 300000 | G5: 24261 | H5: 57335 | I5: 86707 | J5: 660 | M5: 2013 | N5: FDTB
A6: 3 | B6: 3 | C6: Con-way Inc | D6: 5580247 | E6: 104546 | F6: 29987 | G6: 11800 | H6: 0 | I6: 40000 | M6: 2013 | N6: CNWY
A7: 4 | B7: 5 | C7: J.B. Hunt Transport Services | D7: 5054980 | E7: 310354 | F7: 16475 | G7: 9686 | H7: 684 | I7: 22699 | J7: 0 | K7: 58745 | L7: 55409 | M7: 2013 | N7: QPMT
A8: 5 | B8: 4 | C8: YRC Worldwide | D8: 4850500 | E8: -136500 | F8: 32000 | G8: 14572 | H8: 0 | I8: 47694 | M8: 2013 | N8: RDWY
A9: 6 | B9: 6 | C9: Schneider National Inc | D9: 3500000 | F9: 16700 | G9: 11540 | H9: 23 | I9: 29800 | J9: 0 | K9: 14300 | M9: 2013 | N9: SCNN
A10: 7 | B10: 7 | C10: Swift Transportation | D10: 3493182 | E10: 114589 | F10: 16671 | G10: 15231 | M10: 2013 | N10: SWFT
A11: 8 | B11: 8 | C11: TransForce Inc. | D11: 3141513 | E11: 154238 | F11: 14240 | G11: 11380 | H11: 0 | I11: 11700 | M11: 2013 | N11: TransForce | O11: not found
A12: 9 | B12: 9 | C12: Landstar System | D12: 2793420 | E12: 129781 | F12: 1369 | G12: 8265 | H12: 258 | I12: 12967 | M12: 2013 | N12: LRGR
A13: 10 | B13: 10 | C13: Ryder Supply Chain Solutions | D13: 2280586 | E13: 1945 | F13: 13711 | G13: 3729 | H13: 692 | I13: 6282 | M13: 2013 | N13: Ryder
A14: 11 | B14: 14 | C14: Old Dominion Freight Line | D14: 2110483 | E14: 169452 | F14: 14334 | G14: 6099 | H14: 106 | I14: 24181 | L14: 68 | M14: 2013 | N14: ODFL
A15: 12 | B15: 13 | C15: Arkansas Best Corp. | D15: 2065999 | E15: -7732 | F15: 11250 | G15: 3835 | H15: 65 | I15: 20079 | M15: 2013 | N15: Arkansas | O15: not found
A16: 13 | B16: 11 | C16: Werner Enterprises | D16: 2036386 | E16: 103034 | F16: 10736 | G16: 6505 | H16: 645 | I16: 23380 | M16: 2013 | N16: WENP
A17: 14 | B17: 12 | C17: Sirva Inc. | D17: 1973000 | G17: 2465 | H17: 1454 | I17: 4074 | M17: 2013 | N17: Sirva | O17: not found
A18: 15 | B18: 15 | C18: Estes Express Lines | D18: 1857598 | F18: 13849 | G18: 6536 | H18: 523 | I18: 24135 | M18: 2013 | N18: EXLA
A19: 16 | B19: 16 | C19: U.S. Xpress Enterprises | D19: 1756464 | F19: 11983 | G19: 7550 | H19: 0 | I19: 21000 | M19: 2013 | N19: USXI
A20: 17 | B20: 17 | C20: Purolator Inc. | D20: 1632291 | F20: 12000 | G20: 487 | H20: 3256 | I20: 1296 | J20: 23 | M20: 2013 | N20: Purolator | O20: not found
A21: 18 | B21: 18 | C21: UniGroup Inc. | D21: 1613124 | F21: 980 | G21: 6260 | H21: 4415 | I21: 9950 | K21: 14300 | M21: 2013 | N21: AERM
A22: 19 | B22: 20 | C22: C.R. England Inc. | D22: 1416806 | F22: 6759 | G22: 5238 | H22: 0 | I22: 7259 | K22: 700 | M22: 2013 | N22: ENGI
A23: 20 | B23: 19 | C23: CRST International | D23: 1257995 | F23: 5128 | G23: 4511 | H23: 0 | I23: 7570 | M23: 2013 | N23: CRFR
A24: 21 | B24: 23 | C24: Prime Inc. | D24: 1152569 | E24: 147281 | F24: 4450 | G24: 4985 | H24: 0 | I24: 8781 | M24: 2013 | N24: PDSI
A25: 22 | B25: 22 | C25: Saia Inc. | D25: 1100000 | F25: 8000 | G25: 3662 | H25: 80 | I25: 10407 | M25: 2013 | N25: SAIA
A26: 23 | B26: 26 | C26: Kenan Advantage Group | D26: 1091031 | F26: 6873 | G26: 4767 | H26: 0 | I26: 6229 | M26: 2013 | N26: AVTK
A27: 24 | B27: 32 | C27: Roadrunner Transportation Systems | D27: 1073354 | E27: 37530 | F27: 2491 | G27: 3222 | H27: 0 | I27: 2609 | M27: 2013 | N27: MGAS
A28: 25 | B28: 24 | C28: NFI Industries | D28: 1041230 | F28: 6000 | G28: 2155 | H28: 0 | I28: 7000 | K28: 120 | M28: 2013 | N28: NFAQ
A29: 26 | B29: 39 | C29: Universal Truckload Services Inc | D29: 1037006 | E29: 47688 | F29: 4809 | G29: 4125 | H29: 0 | I29: 6308 | K29: 800 | L29: 844 | M29: 2013 | N29: UTVE
A30: 27 | B30: 27 | C30: Southeastern Freight Lines | D30: 1012908 | F30: 7852 | G30: 3291 | H30: 23 | I30: 9820 | M30: 2013 | N30: SEFL
A31: 28 | B31: 28 | C31: Crete Carrier Corp | D31: 998727 | F31: 5627 | G31: 5500 | H31: 0 | I31: 13494 | M31: 2013 | N31: CRCR
A32: 29 | B32: 29 | C32: Averitt Express | D32: 961560 | G32: 3939 | H32: 43 | I32: 11606 | M32: 2013 | N32: AVRT
A33: 30 | B33: 25 | C33: Penske Logistics | D33: 951000 | F33: 8151 | G33: 1615 | H33: 219 | I33: 2883 | M33: 2013 | N33: PSKL
A34: 31 | B34: 30 | C34: Knight Transportation | D34: 936036 | E34: 64117 | F34: 4600 | G34: 4134 | H34: 0 | I34: 9564 | M34: 2013 | N34: Knight | O34: not found
A35: 32 | B35: 36 | C35: Anderson Trucking Service | D35: 927406 | F35: 1250 | G35: 2209 | H35: 0 | I35: 5400 | M35: 2013 | N35: ANNN
A36: 33 | B36: 31 | C36: Lynden Inc. | D36: 885000 | F36: 2391 | G36: 689 | H36: 55 | I36: 1190 | K36: 5926 | L36: 1644 | M36: 2013 | N36: LTIA
A37: 34 | C37: Cardinal Logistics Management Corp. | D37: 850000 | F37: 5100 | G37: 4066 | H37: 201 | I37: 9930 | M37: 2013 | N37: CHWK
A38: 35 | B38: 38 | C38: Quality Distribution Inc | D38: 842118 | E38: 50076 | F38: 1371 | G38: 2775 | H38: 0 | I38: 6514 | M38: 2013 | N38: QTKI
A39: 36 | B39: 35 | C39: Day & Ross Transportation1 Group | D39: 830642 | F39: 2138 | G39: 1630 | H39: 486 | I39: 3944 | M39: 2013 | N39: DAYR
A40: 37 | B40: 33 | C40: Atlas World Group | D40: 815518 | E40: 5910 | F40: 405 | G40: 2178 | H40: 1562 | I40: 3391 | M40: 2013 | N40: ALQK
...

Sheet For Hire 2010-11
A1: Rank | B1: Rank | C1: Company | D1: Revenue | E1: Net income | F1: Employee | G1: Tractors | H1: Truck &Van | I1: Trailers | J1: aircraft | K1: container | L1: chassis | N1: SCAC_Self
A2: 2011 | B2: 2010 | D2: thousand
A3: Rank | C3: Company | D3: Revenue | E3: NetIncome | F3: NumberEmployees | G3: NumberTractors | H3: NumberTruckVans | I3: NumberTrailers | J3: Aircraft | K3: Container | L3: Chassis | M3: AssetYear | N3: SCAC_Self
A4: 1 | B4: 1 | C4: UPS Inc | D4: 53105000 | E4: 3804000 | F4: 398300 | G4: =101121*12268/(12268+66425) -> 15764.457 | H4: =101121*66425/(12268+66425) -> 85356.543 | I4: 78974 | J4: 230 | M4: 2012 | N4: UPSF
A5: 2 | B5: 2 | C5: FedEx Corp | D5: 42224000 | E5: 1369000 | F5: 300000 | G5: 23692 | H5: 53839 | I5: 84817 | J5: 688 | M5: 2012 | N5: FDTB
A6: 3 | B6: 3 | C6: Con-way Inc | D6: 5289953 | E6: 88443 | F6: 27800 | G6: 11900 | H6: 0 | I6: 34400 | M6: 2012 | N6: CNWY
A7: 4 | B7: 4 | C7: YRC Worldwide | D7: 4868844 | E7: -354517 | F7: 32000 | G7: 15602 | H7: 0 | I7: 51636 | M7: 2012 | N7: RDWY
A8: 5 | B8: 5 | C8: J.B. Hunt Transport Services | D8: 4527000 | E8: 257006 | F8: 15631 | G8: 10287 | H8: 0 | I8: 54506 | K8: 54506 | M8: 2012 | N8: QPMT
A9: 6 | B9: 6 | C9: Schneider National Inc | D9: 3400000 | F9: 17400 | G9: 11700 | H9: 80 | I9: 32000 | K9: 13600 | M9: 2012 | N9: SCNN
A10: 7 | B10: 7 | C10: Swift Transportation | D10: 3333908 | E10: 90550 | F10: 17400 | G10: 15902 | H10: 0 | I10: 50555 | K10: 6210 | M10: 2012 | N10: SWFT
A11: 8 | B11: 10 | C11: TransForce Inc. | D11: 2719907 | E11: 103336 | F11: 14680 | G11: 4906 | H11: 1294 | I11: 10684 | L11: 916 | M11: 2012 | N11: TransForce | O11: not found
A12: 9 | B12: 8 | C12: Landstar System | D12: 2649082 | E12: 113007 | F12: 1351 | G12: 8121 | H12: 250 | I12: 13320 | M12: 2012 | N12: LRGR
A13: 10 | B13: 12 | C13: Ryder Supply Chain Solutions | D13: 2211000 | F13: 12387 | G13: 3503 | H13: 918 | I13: 5526 | M13: 2012 | N13: Ryder | O13: subsidiaries found
A14: 11 | B14: 11 | C14: Werner Enterprises | D14: 2002850 | E14: 103757 | F14: 11033 | G14: 7280 | H14: 0 | I14: 23045 | M14: 2012 | N14: WENP
A15: 12 | B15: 13 | C15: Sirva Inc. | D15: 1957000 | F15: 2700 | G15: 2435 | H15: 1429 | I15: 4104 | M15: 2012 | N15: Sirva | O15: not found
A16: 13 | B16: 14 | C16: Arkansas Best Corp. | D16: 1907609 | E16: 6159 | F16: 10800 | G16: 3989 | H16: 67 | I16: 20209 | M16: 2012 | N16: Arkansas | O16: not found
A17: 14 | B17: 18 | C17: Old Dominion Freight Line | D17: 1882541 | E17: 139470 | F17: 13696 | G17: 5830 | H17: 109 | I17: 22695 | L17: 69 | M17: 2012 | N17: ODFL
A18: 15 | B18: 17 | C18: Estes Express Lines | D18: 170000 | F18: 13605 | G18: 6131 | H18: 433 | I18: 22760 | M18: 2012 | N18: EXLA
A19: 16 | B19: 15 | C19: U.S. Xpress Enterprises | D19: 1695548 | F19: 9666 | G19: 7500 | H19: 150 | I19: 21000 | M19: 2012 | N19: USXI
A20: 17 | B20: 19 | C20: Purolator Inc. | D20: 1633241 | F20: 12000 | G20: 432 | H20: 3342 | I20: 1150 | J20: 22 | M20: 2012 | N20: Purolator | O20: not found
A21: 18 | B21: 16 | C21: UniGroup Inc. | D21: 1580000 | F21: 900 | G21: 5904 | H21: 4810 | I21: 10100 | K21: 8000 | M21: 2012 | N21: AERM
A22: 19 | B22: 26 | C22: CRST International | D22: 1277348 | F22: 5200 | G22: 4413 | H22: 0 | I22: 7569 | M22: 2012 | N22: CRFR
A23: 20 | B23: 21 | C23: C.R. England Inc. | D23: 1079716 | E23: 73038 | F23: 4005 | G23: 4331 | H23: 0 | I23: 6854 | K23: 301 | M23: 2012 | N23: ENGI
A24: 21 | B24: 20 | C24: Greatwide Logistics Services | D24: 1045957 | F24: 3500 | G24: 4252 | H24: 0 | I24: 5355 | M24: 2012 | N24: ATGL
A25: 22 | B25: 23 | C25: Saia Inc. | D25: 1030224 | E25: 11373 | F25: 7900 | G25: 4125 | H25: 130 | I25: 11000 | M25: 2012 | N25: SAIA
A26: 23 | B26: 22 | C26: Prime Inc. | D26: 1017482 | E26: 128399 | F26: 3629 | G26: 4886 | H26: 0 | I26: 7262 | M26: 2012 | N26: PDSI
A27: 24 | B27: 24 | C27: NFI Industries | D27: 1010000 | F27: 6000 | G27: 2044 | H27: 30 | I27: 6840 | K27: 70 | M27: 2012 | N27: NFAQ
A28: 25 | B28: 9 | C28: Penske Logistics | D28: 990000 | F28: 8000 | G28: 2180 | H28: 330 | I28: 2878 | M28: 2012 | N28: PSKL
A29: 26 | B29: 29 | C29: Kenan Advantage Group | D29: 987800 | F29: 6560 | G29: 4380 | H29: 0 | I29: 5771 | M29: 2012 | N29: AVTK
A30: 27 | B30: 27 | C30: Southeastern Freight Lines | D30: 942912 | F30: 7552 | G30: 3368 | H30: 23 | I30: 11496 | M30: 2012 | N30: SEFL
A31: 28 | B31: 25 | C31: Crete Carrier Corp. | D31: 942000 | F31: 5933 | G31: 5266 | H31: 0 | I31: 13330 | M31: 2012 | N31: CRCR
A32: 29 | B32: 28 | C32: Averitt Express | D32: 922000 | G32: 3753 | H32: 44 | I32: 11955 | M32: 2012 | N32: AVRT
A33: 30 | B33: 31 | C33: Knight Transportation | D33: 866199 | E33: 60248 | F33: 4854 | G33: 3976 | H33: 0 | I33: 8986 | L33: 66 | M33: 2012 | N33: Knight | O33: subsidiaries found
A34: 31 | B34: 32 | C34: Lynden Inc. | D34: 850000 | F34: 2298 | G34: 729 | H34: 113 | I34: 2931 | K34: 5704 | L34: 1643 | M34: 2012 | N34: LTIA
A35: 32 | B35: 38 | C35: Roadrunner Transportation Systems | D35: 843627 | E35: 25871 | F35: 1848 | G35: 2320 | H35: 0 | I35: 1225 | M35: 2012 | N35: MGAS
A36: 33 | B36: 30 | C36: Atlas World Group | D36: 808935 | E36: 3532 | F36: 642 | G36: 2153 | H36: 1576 | I36: 4014 | K36: 5648 | M36: 2012 | N36: ALQK
A37: 34 | B37: 34 | C37: Vitran Corp. | D37: 805598 | E37: -14013 | F37: 6282 | G37: 2664 | H37: 194 | I37: 7386 | K37: 517 | L37: 448 | M37: 2012 | N37: VITR
A38: 35 | B38: 37 | C38: Day & Ross Transportation Group1 | D38: 785022 | F38: 4292 | G38: 2124 | H38: 145 | I38: 4026 | M38: 2012 | N38: DAYR
A39: 36 | B39: 39 | C39: Anderson Trucking Service | D39: 762143 | F39: 1150 | G39: 2054 | H39: 0 | I39: 5300 | M39: 2012 | N39: ANNN
A40: 37 | B40: 35 | C40: Ruan Transportation Management Systems | D40: 750915 | F40: 5155 | G40: 3334 | H40: 45 | I40: 5667 | M40: 2012 | N40: RLCF
...

Sheet For Hire 2012-13
A1: Rank 2013 | B1: Rank 2012 | C1: Company | D1: Revenue (000) | E1: Net Income (000) | F1: Employees | G1: Tractors | H1: Trucks & Vans | I1: Trailers | J1: Aircraft | K1: Container | L1: Chassis | M1: SCAC_Self
A2: 1 | B2: 1 | C2: =VLOOKUP('For Hire 2012-13'!B2,'For Hire 2011-12'!$A$4:$C$103,3) -> UPS Inc | D2: 55438000 | E2: 4372000 | F2: 395000 | G2: 103000 | J2: 237 | K2: 33000 | M2: UPSF
A3: 2 | B3: 2 | C3: =VLOOKUP('For Hire 2012-13'!B3,'For Hire 2011-12'!$A$4:$C$103,3) -> FedEx Corp | D3: 45100000 | E3: 2046000 | F3: 300000 | G3: 25028 | H3: 62076 | I3: 92982 | J3: 649 | M3: ELGS
A4: 3 | B4: 4 | C4: =VLOOKUP('For Hire 2012-13'!B4,'For Hire 2011-12'!$A$4:$C$103,3) -> J.B. Hunt Transport Services | D4: 5585000 | E4: 342000 | F4: 18467 | G4: =10397+152+686 -> 11235 | H4: =537+208 -> 745 | I4: 26340 | K4: 68302 | L4: 61948 | M4: QPMT
A5: 4 | B5: 3 | C5: =VLOOKUP('For Hire 2012-13'!B5,'For Hire 2011-12'!$A$4:$C$103,3) -> Con-way Inc | D5: 5473356 | E5: 99152 | F5: 29500 | G5: =11600+267 -> 11867 | I5: 32800 | M5: CNWY
A6: 5 | B6: 5 | C6: =VLOOKUP('For Hire 2012-13'!B6,'For Hire 2011-12'!$A$4:$C$103,3) -> YRC Worldwide | D6: 4865400 | E6: 83600 | F6: 2000 | G6: 14500 | I6: 46500 | M6: RDWY
A7: 6 | B7: 7 | C7: =VLOOKUP('For Hire 2012-13'!B7,'For Hire 2011-12'!$A$4:$C$103,3) -> Swift Transportation | D7: 4118195 | E7: 155422 | F7: 16900 | G7: =6081+6685+5195 -> 17961 | I7: 57310 | K7: 8717 | M7: SWFT
A8: 7 | B8: 6 | C8: =VLOOKUP('For Hire 2012-13'!B8,'For Hire 2011-12'!$A$4:$C$103,3) -> Schneider National Inc | D8: 3600000 | F8: 16900 | G8: =9700+2000 -> 11700 | I8: 31000 | K8: 14500 | M8: SCNN
A9: 8 | B9: 69 | C9: =VLOOKUP('For Hire 2012-13'!B9,'For Hire 2011-12'!$A$4:$C$103,3) -> Comtrak Logistics | D9: 3373898 | E9: 69110 | F9: 1982 | G9: =355+2269 -> 2624 | I9: 448 | K9: 25769 | M9: CMKI
A10: 9 | B10: 8 | C10: =VLOOKUP('For Hire 2012-13'!B10,'For Hire 2011-12'!$A$4:$C$103,3) -> TransForce Inc. | D10: 3019367 | E10: 98754 | F10: 14210 | G10: =4300+7630 -> 11930 | I10: 11200 | M10: TransForce
A11: 10 | B11: 9 | C11: =VLOOKUP('For Hire 2012-13'!B11,'For Hire 2011-12'!$A$4:$C$103,3) -> Landstar System | D11: 2644780 | E11: 146009 | F11: 1217 | G11: 8174 | H11: 258 | I11: 12912 | M11: LRGR
A12: 11 | B12: 10 | C12: =VLOOKUP('For Hire 2012-13'!B12,'For Hire 2011-12'!$A$4:$C$103,3) -> Ryder Supply Chain Solutions | D12: 2383063 | F12: 14312 | G12: 4098 | I12: 6042 | M12: Ryder
A13: 12 | B13: 11 | C13: =VLOOKUP('For Hire 2012-13'!B13,'For Hire 2011-12'!$A$4:$C$103,3) -> Old Dominion Freight Line | D13: 2337648 | E13: 206113 | F13: 14073 | G13: 6296 | H13: 105 | I13: 25052 | L13: 27 | M13: ODFL
A14: 13 | B14: 12 | C14: =VLOOKUP('For Hire 2012-13'!B14,'For Hire 2011-12'!$A$4:$C$103,3) -> Arkansas Best Corp. | D14: 2299549 | E14: 15811 | F14: 11420 | G14: 3791 | H14: 56 | I14: 19650 | M14: Arkansas
A15: 14 | B15: 13 | C15: =VLOOKUP('For Hire 2012-13'!B15,'For Hire 2011-12'!$A$4:$C$103,3) -> Werner Enterprises | D15: 2029183 | E15: 86785 | F15: 11642 | G15: =6380+670 -> 7050 | I15: 21980 | K15: 16 | M15: WENP
A16: 15 | B16: 14 | C16: =VLOOKUP('For Hire 2012-13'!B16,'For Hire 2011-12'!$A$4:$C$103,3) -> Sirva Inc. | D16: 1994200 | E16: 9700 | F16: 2700 | G16: =1+1831 -> 1832 | H16: 506 | I16: 6516 | M16: Sirva
A17: 16 | B17: 15 | C17: =VLOOKUP('For Hire 2012-13'!B17,'For Hire 2011-12'!$A$4:$C$103,3) -> Estes Express Lines | D17: 1948535 | F17: 14909 | G17: 6277 | H17: 398 | I17: 24102 | M17: EXLA
A18: 17 | B18: 18 | C18: =VLOOKUP('For Hire 2012-13'!B18,'For Hire 2011-12'!$A$4:$C$103,3) -> UniGroup Inc. | D18: 1700000 | F18: 1050 | G18: =1+6300 -> 6301 | H18: 4500 | I18: 10000 | K18: 16500 | M18: AERM
A19: 18 | B19: 16 | C19: =VLOOKUP('For Hire 2012-13'!B19,'For Hire 2011-12'!$A$4:$C$103,3) -> U.S. Xpress Enterprises | D19: 1600000 | F19: 9700 | G19: =6800+575+621 -> 7996 | I19: 17000 | M19: USXI
A20: 19 | B20: 17 | C20: =VLOOKUP('For Hire 2012-13'!B20,'For Hire 2011-12'!$A$4:$C$103,3) -> Purolator Inc. | D20: 1575391 | F20: 12000 | G20: 493 | H20: 169 | I20: 1292 | M20: Purolator
A21: 20 | B21: 19 | C21: =VLOOKUP('For Hire 2012-13'!B21,'For Hire 2011-12'!$A$4:$C$103,3) -> C.R. England Inc. | D21: 1495597 | F21: 7352 | G21: =3412+819+267 -> 4498 | I21: 6400 | K21: 1200 | M21: ENGI
A22: 21 | B22: 24 | C22: =VLOOKUP('For Hire 2012-13'!B22,'For Hire 2011-12'!$A$4:$C$103,3) -> Roadrunner Transportation Systems | D22: 1361410 | E22: 48996 | F22: 3325 | G22: =740+2983 -> 3723 | I22: 3429 | M22: MGAS
A23: 22 | B23: 21 | C23: =VLOOKUP('For Hire 2012-13'!B23,'For Hire 2011-12'!$A$4:$C$103,3) -> Prime Inc. | D23: 1300998 | E23: 163439 | F23: 4400 | G23: =2021+3168+158 -> 5347 | I23: 9436 | M23: PDSI
A24: 23 | B24: 23 | C24: =VLOOKUP('For Hire 2012-13'!B24,'For Hire 2011-12'!$A$4:$C$103,3) -> Kenan Advantage Group | D24: 1286631 | F24: 7530 | G24: =4449+488+1364 -> 6301 | I24: 9774 | M24: AVTK
A25: 24 | B25: 20 | C25: =VLOOKUP('For Hire 2012-13'!B25,'For Hire 2011-12'!$A$4:$C$103,3) -> CRST International | D25: 1269899 | F25: 4975 | G25: =1870+1208+1412 -> 4490 | H25: 5 | I25: 7552 | M25: CRFR
A26: 25 | B26: 22 | C26: =VLOOKUP('For Hire 2012-13'!B26,'For Hire 2011-12'!$A$4:$C$103,3) -> Saia Inc. | D26: 1139044 | E26: 43627 | F26: 8400 | G26: 3426 | H26: 35 | I26: 10848 | M26: SAIA
A27: 26 | B27: 25 | C27: =VLOOKUP('For Hire 2012-13'!B27,'For Hire 2011-12'!$A$4:$C$103,3) -> NFI Industries | D27: 1090000 | F27: 7600 | G27: =2050+250 -> 2300 | I27: 7400 | K27: 170 | M27: NFAQ
A28: 27 | B28: 27 | C28: =VLOOKUP('For Hire 2012-13'!B28,'For Hire 2011-12'!$A$4:$C$103,3) -> Southeastern Freight Lines | D28: 1065188 | F28: 8030 | G28: =3082+236 -> 3318 | H28: 23 | I28: 11042 | M28: SEFL
A29: 28 | B29: 26 | C29: =VLOOKUP('For Hire 2012-13'!B29,'For Hire 2011-12'!$A$4:$C$103,3) -> Universal Truckload Services Inc | D29: 1033492 | E29: 50572 | F29: 4339 | G29: =734+3403 -> 4137 | I29: 6198 | K29: 800 | L29: 778 | M29: UTVE
A30: 29 | B30: 29 | C30: =VLOOKUP('For Hire 2012-13'!B30,'For Hire 2011-12'!$A$4:$C$103,3) -> Averitt Express | D30: 1020000 | F30: N/A | G30: 4121 | H30: 42 | I30: 12139 | M30: AVRT
A31: 30 | B31: 28 | C31: =VLOOKUP('For Hire 2012-13'!B31,'For Hire 2011-12'!$A$4:$C$103,3) -> Crete Carrier Corp | D31: 1008165 | F31: 5524 | G31: 5300 | I31: 13614 | M31: CRCR
A32: 31 | B32: 31 | C32: =VLOOKUP('For Hire 2012-13'!B32,'For Hire 2011-12'!$A$4:$C$103,3) -> Knight Transportation | D32: 969237 | E32: 69282 | F32: 4600 | G32: =3539+452 -> 3991 | I32: 9181 | M32: Knight
A33: 32 | B33: 30 | C33: =VLOOKUP('For Hire 2012-13'!B33,'For Hire 2011-12'!$A$4:$C$103,3) -> Penske Logistics | D33: 968000 | F33: 10000 | G33: 1598 | H33: 224 | I33: 2816 | M33: PSKL
A34: 33 | B34: 47 | C34: =VLOOKUP('For Hire 2012-13'!B34,'For Hire 2011-12'!$A$4:$C$103,3) -> Heartland Express | D34: 961525 | E34: 90821 | F34: 5220 | G34: 4878 | I34: 14372 | M34: NDIJ
A35: 34 | B35: 35 | C35: =VLOOKUP('For Hire 2012-13'!B35,'For Hire 2011-12'!$A$4:$C$103,3) -> Quality Distribution Inc | D35: 929810 | E35: 42038 | F35: 1145 | G35: =832+1178+889 -> 2899 | I35: 5255 | M35: QTKI
A36: 35 | B36: 33 | C36: =VLOOKUP('For Hire 2012-13'!B36,'For Hire 2011-12'!$A$4:$C$103,3) -> Lynden Inc. | D36: 875000 | F36: 2540 | G36: =483+187 -> 670 | H36: =32+33 -> 65 | I36: 3612 | K36: 12154 | L36: 1558 | M36: LTIA
A37: 36 | B37: 37 | C37: =VLOOKUP('For Hire 2012-13'!B37,'For Hire 2011-12'!$A$4:$C$103,3) -> Atlas World Group | D37: 844827 | E37: 7747 | F37: 700 | G37: =14+2126 -> 2140 | H37: 1551 | I37: 3922 | M37: ALQK
A38: 37 | B38: 53 | C38: =VLOOKUP('For Hire 2012-13'!B38,'For Hire 2011-12'!$A$4:$C$103,3) -> Jack Cooper Transport Co. | D38: 825000 | F38: 4500 | G38: 4000 | M38: COOJ
A39: 38 | B39: 38 | C39: =VLOOKUP('For Hire 2012-13'!B39,'For Hire 2011-12'!$A$4:$C$103,3) -> Ruan Transportation Management Systems | D39: 807507 | F39: 5088 | G39: 3651 | H39: 39 | I39: 6683 | K39: 302 | M39: RLCF
A40: 39 | B40: 36 | C40: =VLOOKUP('For Hire 2012-13'!B40,'For Hire 2011-12'!$A$4:$C$103,3) -> Day & Ross Transportation1 Group | D40: 796476 | F40: 1734 | G40: =110+136+1366 -> 1612 | H40: 339 | I40: 2629 | L40: 69 | M40: DAYR
...

Sheet For Hire 2013-14
A1: Rank 2014 | B1: Rank 2013 | C1: Company | D1: Revenue (000) | E1: Net Income (000) | F1: Employees | G1: Tractors | H1: Trucks & Vans | I1: Trailers | J1: Aircraft | K1: Container | L1: Chassis | M1: SCAC_Self
A2: 1 | B2: 1 | C2: =VLOOKUP('For Hire 2013-14'!B2,'For Hire 2012-13'!$A$2:$C$101,3) -> UPS Inc | D2: 58232000 | E2: 3032000 | F2: 435000 | G2: 106000 | J2: 237 | K2: 33000 | M2: UPSF
A3: 2 | B3: 2 | C3: =VLOOKUP('For Hire 2013-14'!B3,'For Hire 2012-13'!$A$2:$C$101,3) -> FedEx Corp | D3: 47100000 | E3: 2532000 | F3: 300000 | G3: 26594 | H3: 39211 | I3: 97469 | J3: 673 | M3: ELGS
A4: 3 | B4: 3 | C4: =VLOOKUP('For Hire 2013-14'!B4,'For Hire 2012-13'!$A$2:$C$101,3) -> J.B. Hunt Transport Services | D4: 6165441 | E4: 374792 | F4: 20158 | G4: =1358+11637 -> 12995 | I4: 27731 | K4: 73298 | M4: QPMT
A5: 4 | B5: 4 | C5: =VLOOKUP('For Hire 2013-14'!B5,'For Hire 2012-13'!$A$2:$C$101,3) -> Con-way Inc | D5: 5806069 | E5: 137039 | F5: 30100 | G5: 12100 | I5: 33300 | M5: CNWY
A6: 5 | B6: 5 | C6: =VLOOKUP('For Hire 2013-14'!B6,'For Hire 2012-13'!$A$2:$C$101,3) -> YRC Worldwide | D6: 5068800 | E6: 67700 | F6: 33000 | G6: 6400 | I6: 13000 | M6: RDWY
A7: 6 | B7: 6 | C7: =VLOOKUP('For Hire 2013-14'!B7,'For Hire 2012-13'!$A$2:$C$101,3) -> Swift Transportation | D7: 4298724 | E7: 161151 | F7: 21274 | G7: =6083+7799+4954 -> 18836 | I7: 61652 | K7: 9150 | M7: SWFT
A8: 7 | B8: 7 | C8: =VLOOKUP('For Hire 2013-14'!B8,'For Hire 2012-13'!$A$2:$C$101,3) -> Schneider National Inc | D8: 3900000 | F8: 17450 | G8: =9800+2500 -> 12300 | I8: 32350 | K8: 17500 | M8: SCNN
A9: 8 | B9: 8 | C9: =VLOOKUP('For Hire 2013-14'!B9,'For Hire 2012-13'!$A$2:$C$101,3) -> Comtrak Logistics | D9: 3571126 | E9: 51558 | F9: 2568 | G9: =1218+1759 -> 2977 | I9: 448 | K9: 28341 | M9: CMKI
A10: 9 | B10: 9 | C10: =VLOOKUP('For Hire 2013-14'!B10,'For Hire 2012-13'!$A$2:$C$101,3) -> TransForce Inc. | D10: 3363213 | E10: 138902 | F10: 16050 | G10: =6220+8760 -> 14980 | I10: 18680 | M10: TransForce
A11: 10 | B11: 10 | C11: =VLOOKUP('For Hire 2013-14'!B11,'For Hire 2012-13'!$A$2:$C$101,3) -> Landstar System | D11: 31840790 | E11: 138809 | F11: 1211 | G11: 8662 | H11: 270 | I11: 13732 | M11: LRGR
A12: 11 | B12: 12 | C12: =VLOOKUP('For Hire 2013-14'!B12,'For Hire 2012-13'!$A$2:$C$101,3) -> Old Dominion Freight Line | D12: 2787897 | E12: 267514 | F12: 18804 | G12: 6907 | H12: 116 | I12: 27635 | L12: 376 | M12: ODFL
A13: 12 | B13: 13 | C13: =VLOOKUP('For Hire 2013-14'!B13,'For Hire 2012-13'!$A$2:$C$101,3) -> Arkansas Best Corp. | D13: 2612693 | E13: 46177 | F13: 13238 | G13: 4191 | H13: 56 | I13: 19911 | M13: Arkansas
A14: 13 | B14: 11 | C14: =VLOOKUP('For Hire 2013-14'!B14,'For Hire 2012-13'!$A$2:$C$101,3) -> Ryder Supply Chain Solutions | D14: 2461149 | E14: 122356 | G14: 4098 | I14: 6042 | M14: Ryder
A15: 14 | B15: NA | C15: XPO Logistics | D15: 2356600 | E15: 63600 | F15: 10000 | G15: 6200 | M15: XPOL
A16: 15 | B16: 16 | C16: =VLOOKUP('For Hire 2013-14'!B16,'For Hire 2012-13'!$A$2:$C$101,3) -> Estes Express Lines | D16: 2173000 | F16: 15815 | G16: 6620 | H16: 388 | I16: 24592 | K16: 21 | M16: EXLA
A17: 16 | B17: 14 | C17: =VLOOKUP('For Hire 2013-14'!B17,'For Hire 2012-13'!$A$2:$C$101,3) -> Werner Enterprises | D17: 2139289 | E17: 98650 | F17: 10664 | G17: =6455+650 -> 7105 | I17: 22305 | K17: 1 | M17: WENP
A18: 17 | B18: 21 | C18: =VLOOKUP('For Hire 2013-14'!B18,'For Hire 2012-13'!$A$2:$C$101,3) -> Roadrunner Transportation Systems | D18: 1872816 | E18: 51974 | F18: 4142 | G18: =999+3171 -> 4170 | I18: 5135 | M18: MGAS
A19: 18 | B19: 18 | C19: =VLOOKUP('For Hire 2013-14'!B19,'For Hire 2012-13'!$A$2:$C$101,3) -> U.S. Xpress Enterprises | D19: 1730000 | G19: =6800+970 -> 7770 | I19: 17000 | M19: USXI
A20: 19 | B20: 17 | C20: =VLOOKUP('For Hire 2013-14'!B20,'For Hire 2012-13'!$A$2:$C$101,3) -> UniGroup Inc. | D20: 1700000 | F20: 1150 | G20: =5000+1 -> 5001 | H20: 3700 | I20: 500 | K20: 25000 | M20: AERM
A21: 20 | B21: 23 | C21: =VLOOKUP('For Hire 2013-14'!B21,'For Hire 2012-13'!$A$2:$C$101,3) -> Kenan Advantage Group | D21: 1567453 | F21: 7265 | G21: =4470+399+1586 -> 6455 | I21: 9448 | M21: AVTK
A22: 21 | B22: 22 | C22: =VLOOKUP('For Hire 2013-14'!B22,'For Hire 2012-13'!$A$2:$C$101,3) -> Prime Inc. | D22: 1563413 | E22: 207436 | F22: 4450 | G22: =1782+3966+439 -> 6187 | I22: 10637 | M22: PDSI
A23: 22 | B23: 19 | C23: =VLOOKUP('For Hire 2013-14'!B23,'For Hire 2012-13'!$A$2:$C$101,3) -> Purolator Inc. | D23: 1524071 | F23: 11500 | G23: 489 | H23: =166+3055 -> 3221 | I23: 1286 | M23: Purolator
A24: 23 | B24: 20 | C24: =VLOOKUP('For Hire 2013-14'!B24,'For Hire 2012-13'!$A$2:$C$101,3) -> C.R. England Inc. | D24: 1517290 | F24: 7385 | G24: =3528+427+132 -> 4087 | I24: 5293 | K24: 1642 | M24: ENGI
A25: 24 | B25: 15 | C25: =VLOOKUP('For Hire 2013-14'!B25,'For Hire 2012-13'!$A$2:$C$101,3) -> Sirva Inc. | D25: 1464400 | F25: 2700 | G25: =1+2608 -> 2609 | H25: 1625 | I25: 4263 | M25: Sirva
A26: 25 | B26: 24 | C26: =VLOOKUP('For Hire 2013-14'!B26,'For Hire 2012-13'!$A$2:$C$101,3) -> CRST International | D26: 1351571 | F26: 5129 | G26: =1684+1247+1463 -> 4394 | I26: 7290 | M26: CRFR
A27: 26 | B27: 25 | C27: =VLOOKUP('For Hire 2013-14'!B27,'For Hire 2012-13'!$A$2:$C$101,3) -> Saia Inc. | D27: 1272321 | E27: 51991 | F27: 8900 | G27: 3780 | I27: 11530 | M27: SAIA
A28: 27 | B28: 28 | C28: =VLOOKUP('For Hire 2013-14'!B28,'For Hire 2012-13'!$A$2:$C$101,3) -> Universal Truckload Services Inc | D28: 1191521 | E28: 45370 | F28: 4218 | G28: =1075+3333 -> 4408 | I28: 6291 | K28: 800 | L28: 954 | M28: UTVE
A29: 28 | B29: 27 | C29: =VLOOKUP('For Hire 2013-14'!B29,'For Hire 2012-13'!$A$2:$C$101,3) -> Southeastern Freight Lines | D29: 1171968 | F29: 8299 | G29: =3343+256 -> 3599 | H29: 23 | I29: 11496 | M29: SEFL
A30: 29 | B30: 32 | C30: =VLOOKUP('For Hire 2013-14'!B30,'For Hire 2012-13'!$A$2:$C$101,3) -> Penske Logistics | D30: 1137000 | F30: 13000 | G30: 2054 | H30: 245 | I30: 4918 | M30: PSKL
A31: 30 | B31: 26 | C31: =VLOOKUP('For Hire 2013-14'!B31,'For Hire 2012-13'!$A$2:$C$101,3) -> NFI Industries | D31: 1105000 | F31: 8000 | G31: =2022+242 -> 2264 | I31: 7500 | K31: 170 | M31: NFAQ
A32: 31 | B32: 31 | C32: =VLOOKUP('For Hire 2013-14'!B32,'For Hire 2012-13'!$A$2:$C$101,3) -> Knight Transportation | D32: 1102332 | E32: 102862 | F32: 5526 | G32: =4282+456 -> 4738 | I32: 11487 | M32: Knight
A33: 32 | B33: 30 | C33: =VLOOKUP('For Hire 2013-14'!B33,'For Hire 2012-13'!$A$2:$C$101,3) -> Crete Carrier Corp | D33: 1100000 | F33: 5500 | G33: 5130 | I33: 12883 | M33: CRCR
A34: 33 | B34: 29 | C34: =VLOOKUP('For Hire 2013-14'!B34,'For Hire 2012-13'!$A$2:$C$101,3) -> Averitt Express | D34: 1078000 | G34: 4441 | H34: 45 | I34: 13075 | M34: AVRT
A35: 34 | B35: 46 | C35: =VLOOKUP('For Hire 2013-14'!B35,'For Hire 2012-13'!$A$2:$C$101,3) -> Forward Air Corp. | D35: 1010959 | E35: 61169 | F35: 3600 | G35: =248+1052 -> 1300 | H35: =6+190 -> 196 | I35: 3100 | M35: FAFN
A36: 35 | B36: 35 | C36: =VLOOKUP('For Hire 2013-14'!B36,'For Hire 2012-13'!$A$2:$C$101,3) -> Lynden Inc. | D36: 1000000 | F36: 2652 | G36: =448+158 -> 606 | H36: 17 | I36: 3646 | K36: 8540 | L36: 58 | M36: LTIA
A37: 36 | B37: 34 | C37: =VLOOKUP('For Hire 2013-14'!B37,'For Hire 2012-13'!$A$2:$C$101,3) -> Quality Distribution Inc | D37: 991758 | E37: 20640 | F37: 188 | G37: =922+1343+930 -> 3195 | I37: 3171 | M37: QTKI
A38: 37 | B38: 36 | C38: =VLOOKUP('For Hire 2013-14'!B38,'For Hire 2012-13'!$A$2:$C$101,3) -> Atlas World Group | D38: 878313 | E38: 9542 | F38: 644 | G38: =12+2074 -> 2086 | H38: 784 | I38: 4012 | M38: ALQK
A39: 38 | B39: 41 | C39: =VLOOKUP('For Hire 2013-14'!B39,'For Hire 2012-13'!$A$2:$C$101,3) -> Anderson Trucking Service | D39: 873432 | F39: 1389 | G39: =581+1938 -> 2519 | I39: 6127 | M39: ANNN
A40: 39 | B40: 33 | C40: =VLOOKUP('For Hire 2013-14'!B40,'For Hire 2012-13'!$A$2:$C$101,3) -> Heartland Express | D40: 871355 | E40: 84834 | F40: 4500 | G40: 4776 | I40: 12970 | M40: NDIJ
...

Sheet For Hire 2015-16
A1: Rank 2016 | B1: Rank 2015 | C1: Company | D1: Revenue (millions) | E1: Net Income (millions) | F1: Employees | G1: SCAC
A2: 1 | B2: 1 | C2: UPS Supply Chain Solutions | D2: 3,108 est | E2: 5900 | F2: 12700 | G2: UPSF | H2: UPS Supply Chain Solutions: Freight Forwarding
A3: 2 | B3: 12 | C3: XPO Logistics Inc. | D3: 2,841 est | E3: 5,536 est | G3: XPOL | H3: XPO Logistics LLC
A4: 3 | B4: 2 | C4: J.B. Hunt Transport Services | D4: 2,660 est | E4: 5816 | F4: - | G4: QPMT | H4: J.B. Hunt Transport Services
A5: 4 | B5: 4 | C5: C.H. Robinson Worldwide | D5: 2268 | E5: 13476 | F5: 13159 | G5: N/A
A6: 5 | B6: 5 | C6: Expeditors International of Washington | D6: 2188 | E6: 6617 | F6: 15397 | G6: EXDO | H6: Expeditors International of Washington, Inc.
A7: 6 | B7: 3 | C7: Ryder Supply Chain Solutions | D7: 1,925 est | E7: 2,443 est | F7: - | G7: Ryder | H7: Ryder Supply Chain Solutions
A8: 7 | B8: 6 | C8: DHL Supply Chain | D8: 1815 | E8: 3300 | F8: - | G8: DMAL | H8: DHL Global Forwarding
A9: 8 | B9: 10 | C9: FedEx Corp. | D9: 1,625 est | E9: 3178 | F9: - | G9: FDTB | H9: FedEx Corp
A10: 9 | B10: 7 | C10: Ceva Logistics | D10: 1,570 est | E10: 2452 | F10: - | G10: COUT | H10: CEVA Logistics, U.S.: cout
A11: 10 | B11: 8 | C11: Americold Logistics | D11: 1,555 est | E11: - | F11: - | G11: AEID | H11: Americold Transportation Services: US
A12: 11 | B12: 9 | C12: UTi Worldwide | D12: 1,330 est | E12: 3,696 est | F12: - | G12: N/A | H12: UTi Distribution, Inc.
A13: 12 | B13: 11 | C13: Schneider | D13: 1,275 est | E13: 3,480 est | F13: - | G13: N/A | H13: Schneider: Schneider Logistics Division
A14: 13 | B14: 13 | C14: Kuehne + Nagel Inc. | D14: 1197 | E14: 5230 | F14: - | G14: KHNN | H14: Kuehne + Nagel Inc.
A15: 14 | B15: 15 | C15: Penske Logistics | D15: 1,150 est | E15: 1,430 est | F15: 13750 | G15: PSKL | H15: Penske Logistics
A16: 15 | B16: 16 | C16: NFI | D16: 1130 | E16: 1200 | F16: 8101 | G16: NFIL,NFAV,NFBR,NFCV,NFIA,NFIH,NFIV,NFTG,NAFT,NAFQ,NFIV | H16: NFI: NFI Transportation
A17: 16 | B17: 14 | C17: Swift Transportation | D17: 1,065 est | E17: 1,418 est | F17: 120 | G17: SWFT | H17: Swift Transportation
A18: 17 | B18: 20 | C18: DB Schenker USA | D18: 898 | E18: 2687 | F18: - | G18: N/A
A19: 18 | B19: 19 | C19: Neovia Logistics | D19: 860 | E19: - | F19: - | G19: N/A
A20: 19 | B20: 17 | C20: Werner Global Logistics | D20: 826 | E20: 1052 | F20: 4933 | G20: N/A
A21: 20 | B21: 18 | C21: Ruan | D21: 816 | E21: 869 | F21: 5558 | G21: RLCF,RUAN | H21: Ruan Transportation Management Systems, Inc.: Ruan Transport Corporation
A22: 21 | B22: - | C22: Lineage Logistics | D22: 800 | E22: - | F22: - | G22: N/A
A23: 22 | B23: 24 | C23: OHL | D23: 732 est | E23: 1470 | F23: 8000 | G23: OHSQ | H23: OHL: Logistics
A24: 23 | B24: 22 | C24: Cardinal Logistics Holdings | D24: 681 est | E24: - | F24: - | G24: N/A
A25: 24 | B25: 23 | C25: APL Logistics | D25: 660 est | E25: 1030 | F25: 6000 | G25: APDD | H25: APL Logistics: AUTO
A26: 25 | B26: 27 | C26: Kenco Group | D26: 535 | E26: 582 | F26: 3800 | G26: KLSV | H26: Kenco Transportation Services
A27: 26 | B27: 26 | C27: Panalpina Inc. | D27: 459 | E27: 2784 | F27: - | G27: PALA | H27: Panalpina, Inc.
A28: 27 | B28: 33 | C28: Total Quality Logistics | D28: 446 | E28: 2240 | F28: 3791 | G28: TQYL | H28: Total Quality Logistics: Total Quality Logistics
A29: 28 | B29: 30 | C29: Universal Logistics Holdings Inc. | D29: 444 | E29: - | F29: - | G29: ULSV | H29: Universal Logistics Services, Inc: Freight Brokerage
A30: 29 | B30: 31 | C30: Hub Group | D30: 413 | E30: 3526 | F30: 2633 | G30: HUBG,HHWY | H30: Hub Group: Highway
A31: 30 | B31: 34 | C31: DSC Logistics | D31: 405 | E31: - | F31: - | G31: DRSC | H31: DSC Logistics: DSC Logistics
A32: 31 | B32: 32 | C32: Saddle Creek Logistics Services | D32: 390 | E32: - | F32: 2587 | G32: SDLC | H32: Saddle Creek Transportation Inc.
A33: 32 | B33: 28 | C33: U.S. Xpress Inc. | D33: 351 | E33: 508 | F33: - | G33: USXI | H33: U.S. Xpress
A34: 33 | B34: 40 | C34: BDP International | D34: 297 | E34: 1900 | F34: - | G34: N/A
A35: 34 | B35: 36 | C35: Landstar System | D35: 292 est | E35: 1,760 est | F35: 1223 | G35: LRGR | H35: Landstar System
A36: 35 | B36: 45 | C36: Echo Global Logistics | D36: 290 | E36: 1512 | F36: 2335 | G36: ECHS | H36: Echo Global Logistics
A37: 36 | B37: 35 | C37: Toll Global Forwarding | D37: 285 | E37: 1448 | F37: - | G37: N/A
A38: 37 | B38: 37 | C38: Performance Team | D38: 278 | E38: 279 | F38: 4300 | G38: PFYM | H38: Performance Team
A39: 38 | B39: 38 | C39: Burris Logistics | D39: 275 | E39: 3524 | F39: - | G39: N/A
A40: 39 | B40: 42 | C40: Preferred Freezer Services | D40: 265 est | E40: 324 | F40: 1525 | G40: PFBE | H40: Preferred Freezer Logistics
...

Sheet For Hire 2016-17
A1: Rank 2017 | B1: Rank 2016 | C1: Company | D1: Revenue(000) | E1: Net income(000) | F1: Employees | G1: Tractors | H1: Trailers | I1: SCAC
A2: 1 | B2: 1 | C2: UPS Inc. | D2: 60906000 | E2: 3431000 | F2: 434000 | G2: - | H2: - | I2: =VLOOKUP(C2,Sheet1!A1:B3381,2) -> UPSF
A3: 2 | B3: 2 | C3: FedEx Corp. | D3: 57570000 | E3: 1907000 | F3: 400000 | G3: 29733 | H3: 108041 | I3: =VLOOKUP(C3,Sheet1!A2:B3382,2) -> N/A
A4: 3 | B4: 3 | C4: XPO Logistics | D4: 14619400 | E4: 63100 | F4: 89000 | G4: 15396 | H4: 27606 | I4: =VLOOKUP(C4,Sheet1!A3:B3383,2) -> URBS
A5: 4 | B5: 4 | C5: J.B. Hunt Transport Services Inc. | D5: 6555459 | E5: 432090 | F5: 22172 | G5: 14805 | H5: 30330 | I5: =VLOOKUP(C5,Sheet1!A4:B3384,2) -> JEZT
A6: 5 | B6: 5 | C6: YRC Worldwide | D6: 4697500 | E6: 21500 | F6: 32000 | G6: 14300 | H6: 44500 | I6: =VLOOKUP(C6,Sheet1!A5:B3385,2) -> YARB
A7: 6 | B7: 7 | C7: Schneider | D7: 4045736 | E7: 156851 | F7: 19300 | G7: 10459 | H7: 37910 | I7: =VLOOKUP(C7,Sheet1!A6:B3386,2) -> SSIV
A8: 7 | B8: 6 | C8: Swift Transportation | D8: 4031517 | E8: 149267 | F8: 21900 | G8: 18366 | H8: 64066 | I8: =VLOOKUP(C8,Sheet1!A7:B3387,2) -> SDPO
A9: 8 | B9: 8 | C9: Hub Group | D9: 3572790 | E9: 74805 | F9: 2755 | G9: 2705 | H9: 436 | I9: =VLOOKUP(C9,Sheet1!A8:B3388,2) -> N/A
A10: 9 | B10: 9 | C10: Landstar System | D10: 3167634 | E10: 137350 | F10: 1197 | G10: 9186 | H10: 15170 | I10: =VLOOKUP(C10,Sheet1!A9:B3389,2) -> JEAC
A11: 10 | B11: 10 | C11: TFI International | D11: 3037205 | E11: 482592 | F11: 17685 | G11: 18535 | H11: 25310 | I11: =VLOOKUP(C11,Sheet1!A10:B3390,2) -> TRXP
A12: 11 | B12: 11 | C12: Old Dominion Freight Line Inc. | D12: 2991517 | E12: 295765 | F12: 19040 | G12: 7994 | H12: 32525 | I12: =VLOOKUP(C12,Sheet1!A11:B3391,2) -> OIXI
A13: 12 | B13: 12 | C13: ArcBest | D13: 2700219 | E13: 18652 | F13: 13000 | G13: 4387 | H13: 21361 | I13: =VLOOKUP(C13,Sheet1!A12:B3392,2) -> ACTC
A14: 13 | B14: 13 | C14: Ryder Supply Chain Solutions | D14: 2658745 | E14: 169172 | F14: - | G14: 67900 | H14: 42800 | I14: =VLOOKUP(C14,Sheet1!A13:B3393,2) -> N/A
A15: 14 | B15: 14 | C15: Estes Express Lines | D15: 2400000 | E15: - | F15: 16570 | G15: 7009 | H15: 26718 | I15: =VLOOKUP(C15,Sheet1!A14:B3394,2) -> ESNL
A16: 15 | B16: 16 | C16: Roadrunner Transportation Systems Inc. | D16: 2044000 | E16: - | F16: 4645 | G16: 4332 | H16: 6508 | I16: =VLOOKUP(C16,Sheet1!A15:B3395,2) -> RRIS
A17: 16 | B17: 15 | C17: Werner Enterprises Inc. | D17: 2008991 | E17: 79129 | F17: 11738 | G17: 7100 | H17: 24350 | I17: =VLOOKUP(C17,Sheet1!A16:B3396,2) -> WENG
A18: 17 | B18: 17 | C18: UniGroup Inc. | D18: 1700000 | E18: - | F18: - | G18: - | H18: - | I18: =VLOOKUP(C18,Sheet1!A17:B3397,2) -> UNMC
A19: 18 | B19: 18 | C19: Prime Inc. | D19: 1683834 | E19: 194247 | F19: 3661 | G19: 6246 | H19: 12309 | I19: =VLOOKUP(C19,Sheet1!A18:B3398,2) -> PMYT
A20: 19 | B20: 24 | C20: CRST International | D20: 1546000 | E20: - | F20: 7849 | G20: 6682 | H20: 13811 | I20: =VLOOKUP(C20,Sheet1!A19:B3399,2) -> CRPS
A21: 20 | B21: 26 | C21: Purolator Holdings Ltd. | D21: 1526207 | E21: - | F21: 10000 | G21: 463 | H21: 1280 | I21: =VLOOKUP(C21,Sheet1!A20:B3400,2) -> PTAM
A22: 21 | B22: 23 | C22: Penske Logistics | D22: 1500000 | E22: - | F22: 14180 | G22: 2704 | H22: 8785 | I22: =VLOOKUP(C22,Sheet1!A21:B3401,2) -> PENM
A23: 21 | B23: 20 | C23: Sirva Inc. | D23: 1400000 | E23: - | F23: - | G23: - | H23: - | I23: =VLOOKUP(C23,Sheet1!A22:B3402,2) -> SGHE
A24: 21 | B24: 19 | C24: U.S. Xpress Enterprises | D24: 1500000 | E24: - | F24: 10135 | G24: 7000 | H24: 15500 | I24: =VLOOKUP(C24,Sheet1!A23:B3403,2) -> USDI
A25: 24 | B25: - | C25: R+L Carriers | D25: 1452000 | E25: - | F25: 10000 | G25: 5958 | H25: 12604 | I25: =VLOOKUP(C25,Sheet1!A24:B3404,2) -> HRSD
A26: 25 | B26: 21 | C26: Kenan Advantage Group Inc. | D26: 1421975 | E26: - | F26: 7561 | G26: 6869 | H26: 10404 | I26: =VLOOKUP(C26,Sheet1!A25:B3405,2) -> GRHA
A27: 26 | B27: 23 | C27: C.R. England Inc. | D27: 1304898 | E27: - | F27: 7883 | G27: 4165 | H27: 5990 | I27: =VLOOKUP(C27,Sheet1!A26:B3406,2) -> CORV
A28: 27 | B28: 27 | C28: NFI | D28: 1250000 | E28: - | F28: 8300 | G28: 2793 | H28: 8300 | I28: =VLOOKUP(C28,Sheet1!A27:B3407,2) -> NSLC
A29: 28 | B29: 25 | C29: Saia Inc. | D29: 1218481 | E29: 48024 | F29: 9000 | G29: 4000 | H29: 13000 | I29: =VLOOKUP(C29,Sheet1!A28:B3408,2) -> SAGE
A30: 29 | B30: 28 | C30: Southeastern Freight Lines | D30: 1192296 | E30: - | F30: 8458 | G30: 3734 | H30: 11943 | I30: =VLOOKUP(C30,Sheet1!A29:B3409,2) -> SXSQ
A31: 30 | B31: 29 | C31: Knight-Swift Transportation Holdings | D31: 1118034 | E31: 93863 | F31: 5500 | G31: 4705 | H31: 9915 | I31: =VLOOKUP(C31,Sheet1!A30:B3410,2) -> KNIG,KTMW,KNBK,KNIB,KNIM,KTPS
A32: 31 | B32: 32 | C32: Averitt Express | D32: 1091475 | E32: - | F32: - | G32: 4500 | H32: 14623 | I32: =VLOOKUP(C32,Sheet1!A31:B3411,2) -> AVOG
A33: 32 | B33: 30 | C33: Universal Logistics Holdings | D33: 1072751 | E33: 24244 | F33: 6275 | G33: 3801 | H33: 4154 | I33: =VLOOKUP(C33,Sheet1!A32:B3412,2) -> UFER
A34: 33 | B34: 32 | C34: Celadon Group Inc. | D34: 1050000 | E34: 2700 | F34: 6000 | G34: 7050 | H34: 15000 | I34: =VLOOKUP(C34,Sheet1!A33:B3413,2) -> CEJT
A35: 34 | B35: 37 | C35: Anderson Trucking Service | D35: 1032144 | E35: - | F35: 1410 | G35: 2372 | H35: 6300 | I35: =VLOOKUP(C35,Sheet1!A34:B3414,2) -> #N/A
A36: 35 | B36: 33 | C36: Crete Carrier Corp. | D36: 1030000 | E36: - | F36: 5500 | G36: 5130 | H36: 12883 | I36: =VLOOKUP(C36,Sheet1!A35:B3415,2) -> CRAW
A37: 36 | B37: - | C37: Cardinal Logistics Holdings | D37: 1000600 | E37: - | F37: 4642 | G37: 3020 | H37: 9725 | I37: =VLOOKUP(C37,Sheet1!A36:B3416,2) -> N/A
A38: 37 | B38: 35 | C38: Forward Air Corp. | D38: 982530 | E38: 27670 | F38: 3689 | G38: 935 | H38: 4868 | I38: =VLOOKUP(C38,Sheet1!A37:B3417,2) -> FTNA
A39: 38 | B39: 36 | C39: KLLM Transport Services | D39: 937000 | E39: - | F39: - | G39: 3815 | H39: 5300 | I39: =VLOOKUP(C39,Sheet1!A38:B3418,2) -> KLMI
A40: 39 | B40: 34 | C40: Lynden Inc. | D40: 925000 | E40: - | F40: 2800 | G40: 768 | H40: 2889 | I40: =VLOOKUP(C40,Sheet1!A39:B3419,2) -> LNWT
...

Sheet For Hire 2017-18
A1: Rank 2018 | B1: Rank 2017 | C1: Company | D1: Revenue(000) | E1: Net income(000) | F1: Employees | G1: Tractors | H1: Trailers | I1: SCAC
A2: 1 | B2: 1 | C2: UPS Inc. | D2: 65872000 | E2: 4910000 | F2: 454000 | G2: 18683 | H2: 97746 | I2: UPSF | J2: UPS Inc
A3: 2 | B3: 2 | C3: FedEx Corp. | D3: 63864000 | E3: 4465000 | F3: 425000 | G3: 29873 | H3: 113218 | I3: FDTB | J3: FedEx Corp
A4: 3 | B4: 3 | C4: XPO Logistics | D4: 15380800 | E4: 312400 | F4: 95000 | G4: 16287 | H4: 27591 | I4: XPOL | J4: XPO Logistics
A5: 4 | B5: 4 | C5: J.B. Hunt Transport Services Inc. | D5: 7189568 | E5: 385308 | F5: 27670 | G5: 14392 | H5: 32931 | I5: QPMT | J5: J.B. Hunt Transport Services
A6: 5 | B6: 30 | C6: Knight-Swift Transportation Holdings | D6: 5136261 | E6: 529922 | F6: 25400 | G6: 23069 | H6: 74949 | I6: N/A
A7: 6 | B7: 5 | C7: YRC Worldwide | D7: 4891000 | E7: -10800 | F7: 32000 | G7: 14100 | H7: 44600 | I7: RDWY | J7: YRC Worldwide
A8: 7 | B8: 6 | C8: Schneider | D8: 4383600 | E8: 389900 | F8: 19600 | G8: 11859 | H8: 37637 | I8: N/A | J8: Schneider: Schneider Logistics Division
A9: 8 | B9: 9 | C9: Hub Group | D9: 4034897 | E9: 135153 | F9: 4377 | G9: 3520 | H9: 5850 | I9: HUBG,HHWY | J9: Hub Group: Highway
A10: 9 | B10: 10 | C10: TFI International | D10: 3906575 | E10: 130181 | F10: 17044 | G10: 16132 | H10: 24617 | I10: N/A
A11: 10 | B11: 9 | C11: Landstar System | D11: 3646364 | E11: 177088 | F11: 1273 | G11: 9438 | H11: 15534 | I11: LRGR | J11: Landstar System
A12: 11 | B12: 11 | C12: Old Dominion Freight Line Inc. | D12: 3358112 | E12: 463774 | F12: 20944 | G12: 8316 | H12: 32890 | I12: ODFL | J12: Old Dominion Freight Line, Inc.
A13: 12 | B13: 13 | C13: Ryder Supply Chain Solutions | D13: 3065500 | E13: 158400 | F13: - | G13: - | H13: - | I13: Ryder | J13: Ryder Supply Chain Solutions
A14: 13 | B14: 12 | C14: ArcBest | D14: 2826457 | E14: 59726 | F14: 13000 | G14: 4436 | H14: 22275 | I14: KNIG,KTMW,KNBK,KNIB,KNIM,KTPS | J14: ArcBest
A15: 14 | B15: 14 | C15: Estes Express Lines | D15: 2740000 | E15: - | F15: 17397 | G15: 6695 | H15: 27443 | I15: EXLA | J15: Estes Express Lines
A16: 15 | B16: 16 | C16: Werner Enterprises Inc. | D16: 2116737 | E16: 92000 | F16: 12154 | G16: 7480 | H16: 24500 | I16: WENP,WEND,WENL,WGLL,WENF,WMMD,WEDV,WERN,WVAS,WMMI,WVAD,WRBH | J16: Werner Enterprises
A17: 16 | B17: 15 | C17: Roadrunner Transportation Systems Inc. | D17: 2091300 | E17: -91200 | F17: 4600 | G17: 3625 | H17: 6920 | I17: RDFS | J17: Roadrunner Transportation Services, Inc.
A18: 17 | B18: 27 | C18: NFI | D18: 1910000 | E18: - | F18: 10000 | G18: 4000 | H18: 8900 | I18: NFIL,NFAV,NFBR,NFCV,NFIA,NFIH,NFIV,NFTG,NAFT,NAFQ,NFIV | J18: NFI: NFI Transportation
A19: 18 | B19: 18 | C19: Prime Inc. | D19: 1875031 | E19: 208184 | F19: 4300 | G19: 6296 | H19: 12753 | I19: PDSI | J19: Prime Inc
A20: 19 | B20: 21 | C20: Penske Logistics | D20: 1700000 | E20: - | F20: 18011 | G20: 2935 | H20: 9108 | I20: PSKL | J20: Penske Logistics
A21: 19 | B21: 17 | C21: UniGroup Inc. | D21: 1700000 | E21: - | F21: - | G21: - | H21: - | I21: AERM | J21: UniGroup Inc.
A22: 21 | B22: 21 | C22: U.S. Xpress Enterprises | D22: 1600000 | E22: - | F22: 9522 | G22: 6600 | H22: 16800 | I22: USXI | J22: U.S. Xpress Enterprises
A23: 22 | B23: 24 | C23: R+L Carriers | D23: 1580000 | E23: - | F23: - | G23: 5084 | H23: 15675 | I23: N/A
A24: 23 | B24: 19 | C24: CRST International | D24: 1555000 | E24: - | F24: 7538 | G24: 5774 | H24: 12145 | I24: CRFR | J24: CRST International
A25: 24 | B25: 25 | C25: Kenan Advantage Group Inc. | D25: 1441440 | E25: - | F25: 9000 | G25: 6686 | H25: 10744 | I25: AVTK,BLKE,KAGW,KNTC,NOCP,POCN,DTCH,TRAP,CRYI,KEJB | J25: Kenan Advantage
A26: 25 | B26: 26 | C26: C.R. England Inc. | D26: 1405411 | E26: - | F26: 7975 | G26: 4213 | H26: 6116 | I26: ENGI | J26: C.R. England Inc.
A27: 26 | B27: 21 | C27: Sirva Inc. | D27: 1400000 | E27: - | F27: - | G27: - | H27: - | I27: Sirva | J27: Sirva Inc.
A28: 27 | B28: 28 | C28: Saia Inc. | D28: 1378510 | E28: 91156 | F28: 9800 | G28: 4259 | H28: 13901 | I28: SAIA | J28: Saia Inc.
A29: 28 | B29: 20 | C29: Purolator Holdings Ltd. | D29: 1343111 | E29: - | F29: 10000 | G29: 465 | H29: 1329 | I29: N/A
A30: 29 | B30: 42 | C30: Daseke Inc. | D30: 1300000 | E30: 26996 | F30: 4700 | G30: 5200 | H30: 11500 | I30: Daseke | J30: Daseke Inc.
A31: 30 | B31: 29 | C31: Southeastern Freight Lines | D31: 1260050 | E31: - | F31: 8792 | G31: 3635 | H31: 11697 | I31: SEFL | J31: Southeastern Freight Lines
A32: 31 | B32: 32 | C32: Universal Logistics Holdings | D32: 1216665 | E32: 28153 | F32: 8231 | G32: 3784 | H32: 5765 | I32: ULSV | J32: Universal Logistics Services, Inc: Freight Brokerage
A33: 32 | B33: 31 | C33: Averitt Express | D33: 1146970 | E33: 98967 | F33: 8500 | G33: 4513 | H33: 14585 | I33: AVRT | J33: Averitt Express
A34: 33 | B34: 37 | C34: Forward Air Corp. | D34: 1100816 | E34: 87321 | F34: 4898 | G34: 964 | H34: 6464 | I34: FAFN | J34: Forward Air Corp
A35: 34 | B35: 35 | C35: Crete Carrier Corp. | D35: 1100000 | E35: - | F35: 6000 | G35: 5400 | H35: 14000 | I35: CRCR | J35: Crete Carrier Corp
A36: 35 | B36: 33 | C36: Celadon Group Inc. | D36: 1065356 | E36: - | F36: 5200 | G36: 3850 | H36: 10000 | I36: CDNK,CNGV,CELU,CDER,CELZ,CDFK,OSTP | J36: Celadon Group, Inc.: Celadon Trucking
A37: 36 | B37: 34 | C37: Anderson Trucking Service | D37: 1004301 | E37: - | F37: 1996 | G37: 2652 | H37: 6958 | I37: ANNN | J37: Anderson Trucking Service
A38: 37 | B38: 38 | C38: KLLM Transport Services | D38: 959000 | E38: - | F38: - | G38: 3800 | H38: 5700 | I38: KLMI | J38: KLLM Transport Services
A39: 38 | B39: 39 | C39: Lynden Inc. | D39: 950000 | E39: - | F39: 2600 | G39: 768 | H39: 2889 | I39: LTIA | J39: Lynden Inc.
A40: 39 | B40: 59 | C40: Evans Network of Cos. | D40: 898000 | E40: - | F40: 376 | G40: 5014 | H40: 550 | I40: EVTW | J40: Evans Network of Cos
...

Sheet SCAC
A1: Performance Rankings | C1: ALL FLEETS
A2: Rankings are from 1-5, 1=Best (Top 20%)
A3: Click down arrows to filter data by column categories. Select one or more items in the dropdown checklists. | L3: =cou -> #NAME?
A4: To seach by name, SCAC or MCN, click CTRL + F to bring up the search dialogue box, then type in the 4 letter SCAC , the 8 digit MCN, or all or part of the company name.
A6: Note: g/tm=g/ton-mile | G6: Performance Rankings and Emission Factors
G7: Grams per Mile | M7: Grams per Ton-Mile
A8: CompanyDivisionName | B8: Mode | C8: SubMode | D8: Fleet Type | E8: SCAC | F8: MCN | G8: g/mile CO2 Rank | H8: g/mile CO2 | I8: g/mile NOx Rank | J8: g/mile NOx | K8: g/mile PM Rank | L8: g/mile PM | M8: g/tm CO2 Rank | N8: g/tm CO2 | O8: g/tm NOx Rank | P8: g/tm NOx | Q8: g/tm PM Rank | R8: g/tm PM | T8: SCAC_Self
A9: 1st Choice Logistics LLC | B9: Logistics | C9: Logistics | E9: FCOS | F9: MC833561 | G9: 5 | H9: 2460 | I9: 5 | J9: 28.5 | K9: 5 | L9: 1.275 | M9: 5 | N9: 492.5 | O9: 5 | P9: 3.35 | Q9: 5 | R9: 0.177 | T9: FCOS
A10: 3 Rivers Logistics, Inc | B10: Logistics | C10: Logistics | E10: TVQI | F10: MC376181 | G10: 5 | H10: 2460 | I10: 5 | J10: 28.5 | K10: 4 | L10: 1.025 | M10: 5 | N10: 492.5 | O10: 5 | P10: 3.35 | Q10: 4 | R10: 0.139 | T10: TVQI
A11: A & Z Trucking, Inc. | B11: Logistics | C11: Logistics | E11: AZTD | F11: MC510449 | G11: 5 | H11: 2460 | I11: 5 | J11: 28.5 | K11: 4 | L11: 1.025 | M11: 5 | N11: 492.5 | O11: 5 | P11: 3.35 | Q11: 4 | R11: 0.139 | T11: AZTD
A12: A&R Global Logistics | B12: Logistics | C12: Logistics | E12: AMLQ | F12: MC316077 | G12: 4 | H12: 2250 | I12: 3 | J12: 18.5 | K12: 3 | L12: 0.775 | M12: 2 | N12: 207.5 | O12: 2 | P12: 1.25 | Q12: 5 | R12: 0.177 | T12: AMLQ
A13: A.M.Transport Services, Inc. | B13: Logistics | C13: Logistics | E13: AMNO | F13: MC224875 | G13: 4 | H13: 2250 | I13: 5 | J13: 28.5 | K13: 4 | L13: 1.025 | M13: 4 | N13: 397.5 | O13: 4 | P13: 2.65 | Q13: 4 | R13: 0.139 | T13: AMNO
A14: Ace Logistics, Inc. | B14: Logistics | C14: Logistics | E14: ACEI | F14: MC411479 | G14: 4 | H14: 2250 | I14: 4 | J14: 23.5 | K14: 4 | L14: 1.025 | M14: 4 | N14: 397.5 | O14: 4 | P14: 2.65 | Q14: 4 | R14: 0.139 | T14: ACEI
A15: Adams Third Wave Logistics LLC: Freight Broker | B15: Logistics | C15: Logistics | E15: AHWE | F15: MC723939 | G15: 1 | H15: 1620 | I15: 1 | J15: 8.5 | K15: 1 | L15: 0.275 | M15: 1 | N15: 112.5 | O15: 1 | P15: 0.55 | Q15: 1 | R15: 0.025 | T15: AHWE
A16: Addison Transportation | B16: Logistics | C16: Logistics | E16: AFDN | F16: MC326834 | G16: 4 | H16: 2250 | I16: 4 | J16: 23.5 | K16: 4 | L16: 1.025 | M16: 4 | N16: 397.5 | O16: 4 | P16: 2.65 | Q16: 4 | R16: 0.139 | T16: AFDN
A17: ADM Logistics, Inc. | B17: Logistics | C17: Logistics | E17: ADOS | F17: MC274764 | G17: 1 | H17: 1620 | I17: 1 | J17: 8.5 | K17: 1 | L17: 0.275 | M17: 2 | N17: 207.5 | O17: 2 | P17: 1.25 | Q17: 2 | R17: 0.063 | T17: ADOS
A18: Advanced Transportation Services, Inc. | B18: Logistics | C18: Logistics | E18: AVDR | F18: MC191784 | G18: 4 | H18: 2250 | I18: 3 | J18: 18.5 | K18: 3 | L18: 0.775 | M18: 3 | N18: 302.5 | O18: 3 | P18: 1.95 | Q18: 3 | R18: 0.101 | T18: AVDR
A19: Aeronet Worldwide: supply chain solutions | B19: Logistics | C19: Logistics | E19: AERG,AERN | F19: MC0033994 | G19: 1 | H19: 1620 | I19: 1 | J19: 8.5 | K19: 1 | L19: 0.275 | M19: 1 | N19: 112.5 | O19: 1 | P19: 0.55 | Q19: 1 | R19: 0.025 | T19: AERG,AERN
A20: AFN, LLC | B20: Logistics | C20: Logistics | E20: AFNW | F20: MC446639 | G20: 3 | H20: 2040 | I20: 3 | J20: 18.5 | K20: 3 | L20: 0.775 | M20: 3 | N20: 302.5 | O20: 3 | P20: 1.95 | Q20: 3 | R20: 0.101 | T20: AFNW
... A595: Zipline Logistics, LLC | B595: Logistics | C595: Logistics | E595: N/A | F595: MC600879 | G595: 1 | H595: 1620 | I595: 1 | J595: 8.5 | K595: 1 | L595: 0.275 | M595: 1 | N595: 112.5 | O595: 1 | P595: 0.55 | Q595: 1 | R595: 0.025 | T595: N/A
A596: C.R. England: Intermodal | B596: Multi-modal | E596: ENGI | F596: MC124679 | H596: 1225 | J596: 18.5 | L596: 0.5 | N596: 30 | P596: 0.425 | R596: 0.014 | T596: ENGI
